<?xml version="1.0" encoding="UTF-8"?>
<testng-results ignored="0" total="1" passed="0" failed="1" skipped="0">
  <reporter-output>
  </reporter-output>
  <suite started-at="2017-12-24T16:56:54Z" name="Default suite" finished-at="2017-12-24T16:56:54Z" duration-ms="175">
    <groups>
    </groups>
    <test started-at="2017-12-24T16:56:54Z" name="Default test" finished-at="2017-12-24T16:56:54Z" duration-ms="175">
      <class name="com.java8.ch06.test.AverageFinderTest">
        <test-method is-config="true" signature="setUp()[pri:0, instance:com.java8.ch06.test.AverageFinderTest@43c1b556]" started-at="2017-12-24T22:26:54Z" name="setUp" finished-at="2017-12-24T22:26:54Z" duration-ms="55" status="PASS">
          <reporter-output>
          </reporter-output>
        </test-method> <!-- setUp -->
        <test-method signature="test()[pri:0, instance:com.java8.ch06.test.AverageFinderTest@43c1b556]" started-at="2017-12-24T22:26:54Z" name="test" finished-at="2017-12-24T22:26:54Z" duration-ms="50" status="FAIL">
          <exception class="java.lang.AssertionError">
            <message>
              <![CDATA[expected [466.0] but found [466.6666666666667]]]>
            </message>
            <full-stacktrace>
              <![CDATA[java.lang.AssertionError: expected [466.0] but found [466.6666666666667]at org.testng.Assert.fail(Assert.java:96)at org.testng.Assert.failNotEquals(Assert.java:776)at org.testng.Assert.assertEqualsImpl(Assert.java:137)at org.testng.Assert.assertEquals(Assert.java:118)at org.testng.Assert.assertEquals(Assert.java:442)at com.java8.ch06.test.AverageFinderTest.test(AverageFinderTest.java:20)at java.base/jdk.internal.reflect.NativeMethodAccessorImpl.invoke0(Native Method)at java.base/jdk.internal.reflect.NativeMethodAccessorImpl.invoke(Unknown Source)at java.base/jdk.internal.reflect.DelegatingMethodAccessorImpl.invoke(Unknown Source)at java.base/java.lang.reflect.Method.invoke(Unknown Source)at org.testng.internal.MethodInvocationHelper.invokeMethod(MethodInvocationHelper.java:124)at org.testng.internal.Invoker.invokeMethod(Invoker.java:571)at org.testng.internal.Invoker.invokeTestMethod(Invoker.java:707)at org.testng.internal.Invoker.invokeTestMethods(Invoker.java:979)at org.testng.internal.TestMethodWorker.invokeTestMethods(TestMethodWorker.java:125)at org.testng.internal.TestMethodWorker.run(TestMethodWorker.java:109)at org.testng.TestRunner.privateRun(TestRunner.java:648)at org.testng.TestRunner.run(TestRunner.java:505)at org.testng.SuiteRunner.runTest(SuiteRunner.java:455)at org.testng.SuiteRunner.runSequentially(SuiteRunner.java:450)at org.testng.SuiteRunner.privateRun(SuiteRunner.java:415)at org.testng.SuiteRunner.run(SuiteRunner.java:364)at org.testng.SuiteRunnerWorker.runSuite(SuiteRunnerWorker.java:52)at org.testng.SuiteRunnerWorker.run(SuiteRunnerWorker.java:84)at org.testng.TestNG.runSuitesSequentially(TestNG.java:1187)at org.testng.TestNG.runSuitesLocally(TestNG.java:1116)at org.testng.TestNG.runSuites(TestNG.java:1028)at org.testng.TestNG.run(TestNG.java:996)at org.testng.remote.AbstractRemoteTestNG.run(AbstractRemoteTestNG.java:114)at org.testng.remote.RemoteTestNG.initAndRun(RemoteTestNG.java:251)at org.testng.remote.RemoteTestNG.main(RemoteTestNG.java:77)]]>
            </full-stacktrace>
          </exception> <!-- java.lang.AssertionError -->
          <reporter-output>
          </reporter-output>
        </test-method> <!-- test -->
      </class> <!-- com.java8.ch06.test.AverageFinderTest -->
    </test> <!-- Default test -->
  </suite> <!-- Default suite -->
</testng-results>
